05:55:35 PM:DEBUG [logger_base.py:14] Mensaje a nivel debug
05:55:35 PM:INFO [logger_base.py:15] Mensaje a nivel info
05:55:35 PM:WARNING [logger_base.py:16] Mensaje a nivel warning
05:55:35 PM:ERROR [logger_base.py:17] Mensaje a nivel error
05:55:35 PM:CRITICAL [logger_base.py:18] Mensaje a nivel critical
06:00:53 PM:DEBUG [logger_base.py:13] Mensaje a nivel debug
06:00:53 PM:INFO [logger_base.py:14] Mensaje a nivel info
06:00:53 PM:WARNING [logger_base.py:15] Mensaje a nivel warning
06:00:53 PM:ERROR [logger_base.py:16] Mensaje a nivel error
06:00:53 PM:CRITICAL [logger_base.py:17] Mensaje a nivel critical
05:27:02 PM:DEBUG [conexion.py:23] Conexion exitosa: <connection object at 0x0000025240322790; dsn: 'user=postgres password=xxx dbname=test_bd host=127.0.0.1 port=5432', closed: 0>
05:29:57 PM:ERROR [conexion.py:26] Ocurrió un error: 
05:31:55 PM:ERROR [conexion.py:26] Ocurrió un error: 
05:39:29 PM:ERROR [conexion.py:26] Ocurrió un error: 
05:39:41 PM:DEBUG [conexion.py:23] Conexion exitosa: <connection object at 0x000001E7A50E2790; dsn: 'user=postgres password=xxx dbname=test_bd host=127.0.0.1 port=5432', closed: 0>
05:41:12 PM:ERROR [conexion.py:26] Ocurrió un error: 
05:41:40 PM:ERROR [conexion.py:26] Ocurrió un error: 
05:42:50 PM:ERROR [conexion.py:26] Ocurrió un error: 
05:43:12 PM:ERROR [conexion.py:26] Ocurrió un error: 
05:43:19 PM:ERROR [conexion.py:26] Ocurrió un error: 
05:43:40 PM:DEBUG [conexion.py:23] Conexion exitosa: <connection object at 0x0000027F02832790; dsn: 'user=postgres password=xxx dbname=test_bd host=127.0.0.1 port=5432', closed: 0>
05:45:02 PM:DEBUG [conexion.py:23] Conexion exitosa: <connection object at 0x000001DD35382790; dsn: 'user=postgres password=xxx dbname=test_bd host=127.0.0.1 port=5432', closed: 0>
05:45:15 PM:ERROR [conexion.py:26] Ocurrió un error: 
06:15:49 PM:ERROR [conexion.py:26] Ocurrió un error: 
06:21:22 PM:DEBUG [conexion.py:23] Conexion exitosa: <connection object at 0x000001CCA8F02790; dsn: 'user=postgres password=xxx dbname=test_bd host=127.0.0.1 port=5432', closed: 0>
06:21:22 PM:ERROR [conexion.py:39] Ocurrió un error: 'NoneType' object has no attribute 'cursor'
